Workbook

Sheet Overview
A1: Cult & Forgotten Cinema Preservation Master Index | F1: =HYPERLINK("#'SEARCH'!A1","🔍 SEARCH") -> 🔍 SEARCH | G1: =HYPERLINK("#'GUIDE'!A1","📚 GUIDE") -> 📚 GUIDE
A2: Pre-1960 foundations + 1960–1999 · 2.062 preservation leads | H2: Tracker v2
H3: Status | I3: ☐ / ☑
A4: Year | B4: Titles | C4: A priority | D4: B priority | E4: C priority | F4: Notes | H4: Per jaar | I4: live counter onderaan
A5: 1960 | B5: =COUNTA('1960'!A2:A500) -> 11 | C5: =COUNTIF('1960'!B2:B500,"A") -> 4 | D5: =COUNTIF('1960'!B2:B500,"B") -> 5 | E5: =COUNTIF('1960'!B2:B500,"C") -> 2 | H5: Genre | I5: vervangt oude tags
A6: 1961 | B6: =COUNTA('1961'!A2:A500) -> 8 | C6: =COUNTIF('1961'!B2:B500,"A") -> 4 | D6: =COUNTIF('1961'!B2:B500,"B") -> 3 | E6: =COUNTIF('1961'!B2:B500,"C") -> 1 | H6: Titelnotitie | I6: klik/hover op titel
A7: 1962 | B7: =COUNTA('1962'!A2:A500) -> 9 | C7: =COUNTIF('1962'!B2:B500,"A") -> 5 | D7: =COUNTIF('1962'!B2:B500,"B") -> 3 | E7: =COUNTIF('1962'!B2:B500,"C") -> 1
A8: 1963 | B8: =COUNTA('1963'!A2:A500) -> 11 | C8: =COUNTIF('1963'!B2:B500,"A") -> 7 | D8: =COUNTIF('1963'!B2:B500,"B") -> 3 | E8: =COUNTIF('1963'!B2:B500,"C") -> 1 | H8: Genre expansion v3
A9: 1964 | B9: =COUNTA('1964'!A2:A500) -> 16 | C9: =COUNTIF('1964'!B2:B500,"A") -> 13 | D9: =COUNTIF('1964'!B2:B500,"B") -> 2 | E9: =COUNTIF('1964'!B2:B500,"C") -> 1 | H9: Focus | I9: Music / Dance / Disco / Rock / Pop
A10: 1965 | B10: =COUNTA('1965'!A2:A500) -> 13 | C10: =COUNTIF('1965'!B2:B500,"A") -> 10 | D10: =COUNTIF('1965'!B2:B500,"B") -> 3 | E10: =COUNTIF('1965'!B2:B500,"C") -> 0 | H10: Nieuwe titels | I10: 60
A11: 1966 | B11: =COUNTA('1966'!A2:A500) -> 18 | C11: =COUNTIF('1966'!B2:B500,"A") -> 13 | D11: =COUNTIF('1966'!B2:B500,"B") -> 3 | E11: =COUNTIF('1966'!B2:B500,"C") -> 2 | H11: Dubbele titels overgeslagen | I11: 10
A12: 1967 | B12: =COUNTA('1967'!A2:A500) -> 16 | C12: =COUNTIF('1967'!B2:B500,"A") -> 13 | D12: =COUNTIF('1967'!B2:B500,"B") -> 3 | E12: =COUNTIF('1967'!B2:B500,"C") -> 0 | H12: Research anchors | I12: BFI / TCM
A13: 1968 | B13: =COUNTA('1968'!A2:A500) -> 23 | C13: =COUNTIF('1968'!B2:B500,"A") -> 19 | D13: =COUNTIF('1968'!B2:B500,"B") -> 2 | E13: =COUNTIF('1968'!B2:B500,"C") -> 2 | H13: Voorbeelden | I13: Grease · Saturday Night Fever · Fame · Flashdance
A14: 1969 | B14: =COUNTA('1969'!A2:A500) -> 14 | C14: =COUNTIF('1969'!B2:B500,"A") -> 9 | D14: =COUNTIF('1969'!B2:B500,"B") -> 5 | E14: =COUNTIF('1969'!B2:B500,"C") -> 0
A15: 1970 | B15: =COUNTA('1970'!A2:A500) -> 64 | C15: =COUNTIF('1970'!B2:B500,"A") -> 17 | D15: =COUNTIF('1970'!B2:B500,"B") -> 46 | E15: =COUNTIF('1970'!B2:B500,"C") -> 1 | H15: Expansion v4
A16: 1971 | B16: =COUNTA('1971'!A2:A500) -> 74 | C16: =COUNTIF('1971'!B2:B500,"A") -> 16 | D16: =COUNTIF('1971'!B2:B500,"B") -> 53 | E16: =COUNTIF('1971'!B2:B500,"C") -> 5 | H16: New focus | I16: Teen / High-Concept | J16: Spoof / Slapstick | K16: Blaxploitation / Black Cult
A17: 1972 | B17: =COUNTA('1972'!A2:A500) -> 72 | C17: =COUNTIF('1972'!B2:B500,"A") -> 28 | D17: =COUNTIF('1972'!B2:B500,"B") -> 41 | E17: =COUNTIF('1972'!B2:B500,"C") -> 3 | H17: Core tags | I17: Teen Sci-Fi Comedy | J17: Spoof / Parody | K17: Blaxploitation
A18: 1973 | B18: =COUNTA('1973'!A2:A500) -> 77 | C18: =COUNTIF('1973'!B2:B500,"A") -> 23 | D18: =COUNTIF('1973'!B2:B500,"B") -> 52 | E18: =COUNTIF('1973'!B2:B500,"C") -> 2 | I18: Body-Swap Comedy | J18: Broad Comedy | K18: Black Comedy
A19: 1974 | B19: =COUNTA('1974'!A2:A500) -> 66 | C19: =COUNTIF('1974'!B2:B500,"A") -> 27 | D19: =COUNTIF('1974'!B2:B500,"B") -> 37 | E19: =COUNTIF('1974'!B2:B500,"C") -> 2 | I19: Fantasy Comedy | J19: Road / Buddy Comedy | K19: Black Cinema
A20: 1975 | B20: =COUNTA('1975'!A2:A500) -> 53 | C20: =COUNTIF('1975'!B2:B500,"A") -> 27 | D20: =COUNTIF('1975'!B2:B500,"B") -> 25 | E20: =COUNTIF('1975'!B2:B500,"C") -> 1 | I20: Geek / Nerd Comedy | J20: Dark Comedy | K20: Black Horror
A21: 1976 | B21: =COUNTA('1976'!A2:A500) -> 63 | C21: =COUNTIF('1976'!B2:B500,"A") -> 24 | D21: =COUNTIF('1976'!B2:B500,"B") -> 37 | E21: =COUNTIF('1976'!B2:B500,"C") -> 2 | I21: Youth Adventure | J21: Institution Comedy | K21: Black Music / Cult
A22: 1977 | B22: =COUNTA('1977'!A2:A500) -> 55 | C22: =COUNTIF('1977'!B2:B500,"A") -> 24 | D22: =COUNTIF('1977'!B2:B500,"B") -> 31 | E22: =COUNTIF('1977'!B2:B500,"C") -> 0
A23: 1978 | B23: =COUNTA('1978'!A2:A500) -> 68 | C23: =COUNTIF('1978'!B2:B500,"A") -> 31 | D23: =COUNTIF('1978'!B2:B500,"B") -> 35 | E23: =COUNTIF('1978'!B2:B500,"C") -> 2 | H23: New films | I23: 169 | J23: Already present | K23: 36
A24: 1979 | B24: =COUNTA('1979'!A2:A500) -> 54 | C24: =COUNTIF('1979'!B2:B500,"A") -> 24 | D24: =COUNTIF('1979'!B2:B500,"B") -> 26 | E24: =COUNTIF('1979'!B2:B500,"C") -> 4 | H24: Research anchor | I24: BFI comedy
A25: 1980 | B25: =COUNTA('1980'!A2:A500) -> 63 | C25: =COUNTIF('1980'!B2:B500,"A") -> 40 | D25: =COUNTIF('1980'!B2:B500,"B") -> 23 | E25: =COUNTIF('1980'!B2:B500,"C") -> 0 | H25: Research anchor | I25: BFI blaxploitation
A26: 1981 | B26: =COUNTA('1981'!A2:A500) -> 90 | C26: =COUNTIF('1981'!B2:B500,"A") -> 36 | D26: =COUNTIF('1981'!B2:B500,"B") -> 54 | E26: =COUNTIF('1981'!B2:B500,"C") -> 0
A27: 1982 | B27: =COUNTA('1982'!A2:A500) -> 84 | C27: =COUNTIF('1982'!B2:B500,"A") -> 44 | D27: =COUNTIF('1982'!B2:B500,"B") -> 35 | E27: =COUNTIF('1982'!B2:B500,"C") -> 5 | H27: Examples | I27: Weird Science | J27: Airplane! | K27: Shaft
A28: 1983 | B28: =COUNTA('1983'!A2:A500) -> 74 | C28: =COUNTIF('1983'!B2:B500,"A") -> 47 | D28: =COUNTIF('1983'!B2:B500,"B") -> 26 | E28: =COUNTIF('1983'!B2:B500,"C") -> 1 | I28: Real Genius | J28: The Naked Gun | K28: Coffy
A29: 1984 | B29: =COUNTA('1984'!A2:A500) -> 69 | C29: =COUNTIF('1984'!B2:B500,"A") -> 40 | D29: =COUNTIF('1984'!B2:B500,"B") -> 28 | E29: =COUNTIF('1984'!B2:B500,"C") -> 1 | I29: Teen Witch | J29: Police Academy | K29: I'm Gonna Git You Sucka
A30: 1985 | B30: =COUNTA('1985'!A2:A500) -> 98 | C30: =COUNTIF('1985'!B2:B500,"A") -> 56 | D30: =COUNTIF('1985'!B2:B500,"B") -> 40 | E30: =COUNTIF('1985'!B2:B500,"C") -> 2
A31: 1986 | B31: =COUNTA('1986'!A2:A500) -> 84 | C31: =COUNTIF('1986'!B2:B500,"A") -> 50 | D31: =COUNTIF('1986'!B2:B500,"B") -> 32 | E31: =COUNTIF('1986'!B2:B500,"C") -> 2 | H31: Expansion v5
A32: 1987 | B32: =COUNTA('1987'!A2:A500) -> 89 | C32: =COUNTIF('1987'!B2:B500,"A") -> 48 | D32: =COUNTIF('1987'!B2:B500,"B") -> 36 | E32: =COUNTIF('1987'!B2:B500,"C") -> 5 | H32: Focus | I32: Post-Apocalyptic | J32: Road Warrior / Mad Max clones | K32: Wasteland / Dystopian DTV
A33: 1988 | B33: =COUNTA('1988'!A2:A500) -> 57 | C33: =COUNTIF('1988'!B2:B500,"A") -> 47 | D33: =COUNTIF('1988'!B2:B500,"B") -> 7 | E33: =COUNTIF('1988'!B2:B500,"C") -> 3 | H33: New films | I33: 61 | J33: Existing reviewed | K33: 14
A34: 1989 | B34: =COUNTA('1989'!A2:A500) -> 48 | C34: =COUNTIF('1989'!B2:B500,"A") -> 40 | D34: =COUNTIF('1989'!B2:B500,"B") -> 5 | E34: =COUNTIF('1989'!B2:B500,"C") -> 3 | H34: Core cycle | I34: Italian post-nuke | J34: Philippine wasteland | K34: 80s/90s DTV
A35: 1990 | B35: =COUNTA('1990'!A2:A500) -> 50 | C35: =COUNTIF('1990'!B2:B500,"A") -> 42 | D35: =COUNTIF('1990'!B2:B500,"B") -> 6 | E35: =COUNTIF('1990'!B2:B500,"C") -> 2 | H35: Adjacent | I35: Arthouse nuclear aftermath | J35: Cyberpunk wasteland | K35: Youth / road dystopia
A36: 1991 | B36: =COUNTA('1991'!A2:A500) -> 46 | C36: =COUNTIF('1991'!B2:B500,"A") -> 39 | D36: =COUNTIF('1991'!B2:B500,"B") -> 6 | E36: =COUNTIF('1991'!B2:B500,"C") -> 1 | H36: Anchors | I36: Mad Max | J36: The Road Warrior | K36: Escape from New York
A37: 1992 | B37: =COUNTA('1992'!A2:A500) -> 48 | C37: =COUNTIF('1992'!B2:B500,"A") -> 46 | D37: =COUNTIF('1992'!B2:B500,"B") -> 2 | E37: =COUNTIF('1992'!B2:B500,"C") -> 0 | H37: Cult examples | I37: 2019: After the Fall of New York | J37: Wheels of Fire | K37: Neon City
A38: 1993 | B38: =COUNTA('1993'!A2:A500) -> 45 | C38: =COUNTIF('1993'!B2:B500,"A") -> 35 | D38: =COUNTIF('1993'!B2:B500,"B") -> 7 | E38: =COUNTIF('1993'!B2:B500,"C") -> 3 | I38: The New Barbarians | J38: Equalizer 2000 | K38: Six-String Samurai
A39: 1994 | B39: =COUNTA('1994'!A2:A500) -> 59 | C39: =COUNTIF('1994'!B2:B500,"A") -> 38 | D39: =COUNTIF('1994'!B2:B500,"B") -> 19 | E39: =COUNTIF('1994'!B2:B500,"C") -> 2 | H39: Research | I39: Mondo Digital / title-specific references
A40: 1995 | B40: =COUNTA('1995'!A2:A500) -> 65 | C40: =COUNTIF('1995'!B2:B500,"A") -> 48 | D40: =COUNTIF('1995'!B2:B500,"B") -> 13 | E40: =COUNTIF('1995'!B2:B500,"C") -> 4 | H40: Source sheet | I40: Post-Apoc Sources
...

Sheet 1960
A1: Title | B1: Priority | C1: Genre | D1: Status | E1: Curator Tags | F1: Source
A2: Black Sunday | B2: A | C2: Gothic Horror | D2: ☐ | E2: Genre Essential | F2: Original Master v1 — curated research basis
A3: Eyes Without a Face | B3: A | C3: Horror — Subgenre Review | D3: ☐ | E3: Cult Canon | F3: Original Master v1 — curated research basis
A4: Peeping Tom | B4: A | C4: Psychological Horror | D4: ☐ | E4: Banned / Controversial | F4: Original Master v1 — curated research basis
A5: Psycho | B5: C | C5: Psychological Horror / Proto-Slasher | D5: ☐ | E5: Canon Anchor | F5: Original Master v1 — curated research basis
A6: The Brides of Dracula | B6: B | C6: Gothic Horror | D6: ☐ | E6: Genre Deep Cut | F6: Original Master v1 — curated research basis
A7: The City of the Dead | B7: B | C7: Occult Horror | D7: ☐ | E7: Genre Deep Cut | F7: Original Master v1 — curated research basis
A8: The Flesh and the Fiends | B8: B | C8: British Horror | D8: ☐ | E8: Genre Deep Cut | F8: Original Master v1 — curated research basis
A9: The Little Shop of Horrors | B9: B | C9: Horror Comedy | D9: ☐ | E9: Genre Deep Cut | F9: Original Master v1 — curated research basis
A10: The Mask of Satan | B10: A | C10: Gothic Horror | D10: ☐ | E10: Genre Essential | F10: Original Master v1 — curated research basis
A11: The Time Machine | B11: C | C11: Sci-Fi | D11: ☐ | E11: Cult Canon / Canon Anchor | F11: Original Master v1 — curated research basis
A12: Village of the Damned | B12: B | C12: Sci-Fi Horror | D12: ☐ | E12: Genre Deep Cut | F12: Original Master v1 — curated research basis
C14: In collectie | D14: =COUNTIF(D2:D12,"☑")&" / "&COUNTA(A2:A12) -> 0 / 11

Sheet 1961
A1: Title | B1: Priority | C1: Genre | D1: Status | E1: Curator Tags | F1: Source
A2: Mothra | B2: A | C2: Kaiju / Tokusatsu / Fantasy Sci-Fi | D2: ☐ | E2: Cult Canon / Genre Essential | F2: SOURCE AUDIT NEEDED — final blind-spot pass
A3: Mysterious Island | B3: B | C3: Fantasy | D3: ☐ | E3: Genre Deep Cut | F3: Original Master v1 — curated research basis
A4: The Beast of Yucca Flats | B4: A | C4: Outsider Cinema / Sci-Fi Horror / Coleman Francis | D4: ☐ | E4: So-Bad-It's-Good / Psychotronic / Regional Oddity | F4: https://en.wikipedia.org/wiki/The_Beast_of_Yucca_Flats
A5: The Curse of the Werewolf | B5: B | C5: Gothic Horror | D5: ☐ | E5: Genre Deep Cut | F5: Original Master v1 — curated research basis
A6: The Day the Earth Caught Fire | B6: A | C6: Post-Apocalyptic / Sci-Fi | D6: ☐ | E6: Genre Essential | F6: Original Master v1 — curated research basis
A7: The Innocents | B7: A | C7: Gothic Horror / Psychological Horror / Unreliable Reality | D7: ☐ | E7: Genre Essential / Visual Cult | F7: Original Master v1 — curated research basis
A8: The Pit and the Pendulum | B8: B | C8: Other / Unclassified | D8: ☐ | E8: Genre Deep Cut / Needs Genre Review | F8: Original Master v1 — curated research basis
A9: Yojimbo | B9: C | C9: Arthouse | D9: ☐ | E9: Canon Anchor | F9: Original Master v1 — curated research basis
C11: In collectie | D11: =COUNTIF(D2:D9,"☑")&" / "&COUNTA(A2:A9) -> 0 / 8

Sheet 1962
A1: Title | B1: Priority | C1: Genre | D1: Status | E1: Curator Tags | F1: Source
A2: Carnival of Souls | B2: A | C2: Psychological Horror / Supernatural Horror | D2: ☐ | E2: Cult Canon | F2: Original Master v1 — curated research basis
A3: Journey to the Seventh Planet | B3: B | C3: Sci-Fi / Fantasy | D3: ☐ | E3: Genre Deep Cut | F3: Original Master v1 — curated research basis
A4: Mondo Cane | B4: A | C4: Mondo Documentary / Shockumentary / Exploitation | D4: ☐ | E4: Genre Foundation / Controversial Cult | F4: SOURCE AUDIT NEEDED — final blind-spot pass
A5: The Awful Dr. Orlof | B5: A | C5: Horror — Subgenre Review | D5: ☐ | E5: Genre Essential | F5: Original Master v1 — curated research basis
A6: The Brain That Wouldn't Die | B6: A | C6: Horror — Subgenre Review | D6: ☐ | E6: Drive-In Classic / Psychotronic | F6: Original Master v1 — curated research basis
A7: The Day of the Triffids | B7: B | C7: Sci-Fi Horror | D7: ☐ | E7: Genre Deep Cut | F7: Original Master v1 — curated research basis
A8: The Fabulous Baron Munchausen | B8: A | C8: Fantasy / Arthouse | D8: ☐ | E8: Genre Essential | F8: Original Master v1 — curated research basis
A9: The Manchurian Candidate | B9: C | C9: Other / Unclassified | D9: ☐ | E9: Cult Canon / Canon Anchor / Needs Genre Review | F9: Original Master v1 — curated research basis
A10: The Premature Burial | B10: B | C10: Other / Unclassified | D10: ☐ | E10: Genre Deep Cut / Needs Genre Review | F10: Original Master v1 — curated research basis
C12: In collectie | D12: =COUNTIF(D2:D10,"☑")&" / "&COUNTA(A2:A10) -> 0 / 9

Sheet 1963
A1: Title | B1: Priority | C1: Genre | D1: Status | E1: Curator Tags | F1: Source
A2: Black Sabbath | B2: A | C2: Horror Anthology / Italian Horror | D2: ☐ | E2: Genre Essential | F2: Original Master v1 — curated research basis
A3: Dementia 13 | B3: A | C3: Gothic Horror | D3: ☐ | E3: Genre Essential | F3: Original Master v1 — curated research basis
A4: Matango | B4: A | C4: Japanese Sci-Fi Horror / Mutation / Island Nightmare | D4: ☐ | E4: Cult Canon / Genre Deep Cut | F4: SOURCE AUDIT NEEDED — final blind-spot pass
A5: The Birds | B5: C | C5: Nature Horror / Animal Attack | D5: ☐ | E5: Canon Anchor | F5: Original Master v1 — curated research basis
A6: The Girl Who Knew Too Much | B6: A | C6: Giallo | D6: ☐ | E6: Genre Foundation | F6: Original Master v1 — curated research basis
A7: The Haunting | B7: A | C7: Gothic Horror | D7: ☐ | E7: Genre Essential | F7: Original Master v1 — curated research basis
A8: The Kiss of the Vampire | B8: B | C8: Gothic Horror | D8: ☐ | E8: Genre Deep Cut | F8: Original Master v1 — curated research basis
A9: The Old Dark House | B9: B | C9: Comedy / Camp | D9: ☐ | E9: Camp Classic | F9: Original Master v1 — curated research basis
A10: The Raven | B10: B | C10: Comedy / Camp | D10: ☐ | E10: Camp Classic | F10: Original Master v1 — curated research basis
A11: The Sadist | B11: A | C11: Thriller / Exploitation | D11: ☐ | E11: Genre Essential | F11: Original Master v1 — curated research basis
A12: The Whip and the Body | B12: A | C12: Other / Unclassified | D12: ☐ | E12: Cult Canon / Needs Genre Review | F12: Original Master v1 — curated research basis
C14: In collectie | D14: =COUNTIF(D2:D12,"☑")&" / "&COUNTA(A2:A12) -> 0 / 11

Sheet 1964
A1: Title | B1: Priority | C1: Genre | D1: Status | E1: Curator Tags | F1: Source
A2: A Hard Day's Night | B2: A | C2: Music / Rock / Comedy | D2: ☐ | E2: Genre Essential | F2: SOURCE AUDIT NEEDED — row-level external source not retained
A3: Blood and Black Lace | B3: A | C3: Giallo / Fashion Horror / Proto-Slasher | D3: ☐ | E3: Cult Canon / Genre Foundation / Visual Cult | F3: SOURCE AUDIT NEEDED — final blind-spot pass
A4: Castle of Blood | B4: A | C4: Gothic Horror | D4: ☐ | E4: Genre Essential | F4: Original Master v1 — curated research basis
A5: Dr. Strangelove | B5: C | C5: Satire | D5: ☐ | E5: Cult Canon / Canon Anchor | F5: Original Master v1 — curated research basis
A6: Kwaidan | B6: A | C6: Arthouse | D6: ☐ | E6: Genre Essential | F6: Original Master v1 — curated research basis
A7: Onibaba | B7: A | C7: Japanese Horror | D7: ☐ | E7: Genre Essential | F7: Original Master v1 — curated research basis
A8: Santa Claus Conquers the Martians | B8: A | C8: Outsider Cinema / Kids Sci-Fi / Christmas Oddity | D8: ☐ | E8: So-Bad-It's-Good / Cult Canon / Psychotronic | F8: https://en.wikipedia.org/wiki/Santa_Claus_Conquers_the_Martians
A9: Spider Baby | B9: A | C9: Horror Comedy | D9: ☐ | E9: Cult Canon | F9: Original Master v1 — curated research basis
A10: The Creeping Terror | B10: A | C10: Outsider Cinema / Creature Sci-Fi / Regional B-Movie | D10: ☐ | E10: So-Bad-It's-Good / Regional Oddity / Cult Canon | F10: https://en.wikipedia.org/wiki/The_Creeping_Terror
A11: The Earth Dies Screaming | B11: B | C11: Sci-Fi Horror | D11: ☐ | E11: Genre Deep Cut | F11: Original Master v1 — curated research basis
A12: The Flesh Eaters | B12: A | C12: Other / Unclassified | D12: ☐ | E12: Genre Foundation / Needs Genre Review | F12: Original Master v1 — curated research basis
... A17: The Umbrellas of Cherbourg | B17: A | C17: Musical / Romance / Arthouse | D17: ☐ | E17: Genre Essential | F17: SOURCE AUDIT NEEDED — row-level external source not retained
C19: In collectie | D19: =COUNTIF(D2:D17,"☑")&" / "&COUNTA(A2:A17) -> 0 / 16

Sheet 1965
A1: Title | B1: Priority | C1: Genre | D1: Status | E1: Curator Tags | F1: Source
A2: Alphaville | B2: A | C2: Sci-Fi / Arthouse | D2: ☐ | E2: Genre Essential | F2: Original Master v1 — curated research basis
A3: Die, Monster, Die! | B3: B | C3: Cosmic Horror | D3: ☐ | E3: Genre Deep Cut | F3: Original Master v1 — curated research basis
A4: Dr. Terror's House of Horrors | B4: B | C4: Other / Unclassified | D4: ☐ | E4: Genre Deep Cut / Needs Genre Review | F4: Original Master v1 — curated research basis
A5: Faster, Pussycat! Kill! Kill! | B5: A | C5: Exploitation | D5: ☐ | E5: Genre Essential | F5: Original Master v1 — curated research basis
A6: Frankenstein Meets the Space Monster | B6: A | C6: Sci-Fi | D6: ☐ | E6: Cult Canon | F6: Original Master v1 — curated research basis
A7: Gamera, the Giant Monster | B7: A | C7: Kaiju / Tokusatsu / Japanese Monster | D7: ☐ | E7: Cult Canon / Genre Foundation | F7: SOURCE AUDIT NEEDED — final blind-spot pass
A8: Help! | B8: A | C8: Music / Rock / Comedy | D8: ☐ | E8: Genre Essential | F8: SOURCE AUDIT NEEDED — row-level external source not retained
A9: Monster a Go-Go | B9: A | C9: Outsider Cinema / Sci-Fi Horror / Regional Oddity | D9: ☐ | E9: So-Bad-It's-Good / Cult Oddity | F9: https://en.wikipedia.org/wiki/Monster_a_Go-Go
A10: Orgy of the Dead | B10: A | C10: Other / Unclassified | D10: ☐ | E10: Psychotronic / Needs Genre Review | F10: Original Master v1 — curated research basis
A11: Planet of the Vampires | B11: A | C11: Sci-Fi Horror | D11: ☐ | E11: Genre Essential | F11: Original Master v1 — curated research basis
A12: Repulsion | B12: A | C12: Psychological Horror / Subjective Horror / Apartment Horror | D12: ☐ | E12: Cult Canon / Genre Essential / Visual Cult | F12: https://whatson.bfi.org.uk/Online/default.asp?BOparam%3A%3AWScontent%3A%3AloadArticle%3A%3Apermalink=repulsion
... A14: The Skull | B14: B | C14: Horror — Subgenre Review | D14: ☐ | E14: Genre Deep Cut | F14: Original Master v1 — curated research basis
C16: In collectie | D16: =COUNTIF(D2:D14,"☑")&" / "&COUNTA(A2:A14) -> 0 / 13

Sheet 1966
A1: Title | B1: Priority | C1: Genre | D1: Status | E1: Curator Tags | F1: Source
A2: Come Drink with Me | B2: A | C2: Classic Hong Kong Kung Fu / Wuxia / Shaw Brothers / Foundation | D2: ☐ | E2: Genre Foundation | F2: https://www.bfi.org.uk/features/where-begin-with-shaw-brothers
A3: Django | B3: A | C3: Western | D3: ☐ | E3: Cult Canon | F3: Original Master v1 — curated research basis
A4: Dracula: Prince of Darkness | B4: B | C4: Gothic Horror | D4: ☐ | E4: Genre Deep Cut | F4: Original Master v1 — curated research basis
A5: Fantastic Voyage | B5: C | C5: Science Adventure / Miniaturization / Medical Sci-Fi | D5: ☐ | E5: Canon Anchor / Genre Foundation | F5: https://en.wikipedia.org/wiki/Fantastic_Voyage
A6: Gamera vs. Barugon | B6: A | C6: Kaiju / Tokusatsu / Monster Battle | D6: ☐ | E6: Franchise Essential / Genre Deep Cut | F6: SOURCE AUDIT NEEDED — final blind-spot pass
A7: Kill, Baby... Kill! | B7: A | C7: Gothic Horror | D7: ☐ | E7: Genre Essential | F7: Original Master v1 — curated research basis
A8: Manos: The Hands of Fate | B8: A | C8: Outsider Cinema / Folk Horror / Amateur Regional | D8: ☐ | E8: So-Bad-It's-Good / Cult Canon / Regional Oddity | F8: https://www.amateurcinema.org/index.php/film/manos-the-hands-of-fate
A9: Persona | B9: C | C9: Psychological Surrealism / Identity Horror / Arthouse | D9: ☐ | E9: Canon Anchor / Genre Foundation / Identity Cinema | F9: https://www.bfi.org.uk/lists/persona-films-inspired-ingmar-bergman-60th-anniversary
A10: Rat Pfink a Boo Boo | B10: A | C10: Outsider Cinema / Superhero Parody / Ray Dennis Steckler | D10: ☐ | E10: Psychotronic / Cult Oddity / Regional Oddity | F10: https://en.wikipedia.org/wiki/Rat_Pfink_a_Boo_Boo
A11: Seconds | B11: A | C11: Paranoid Sci-Fi / Identity Horror / Psychological Thriller | D11: ☐ | E11: Cult Canon / Genre Essential | F11: Original Master v1 — curated research basis
A12: The Big Gundown | B12: A | C12: Spaghetti Western / Political Western / Manhunt | D12: ☐ | E12: Genre Essential / Cult Classic | F12: SOURCE AUDIT NEEDED — final blind-spot pass
... A19: The Wild Angels | B19: A | C19: Biker / Action / Exploitation | D19: ☐ | E19: Genre Essential | F19: Original Master v1 — curated research basis
C21: In collectie | D21: =COUNTIF(D2:D19,"☑")&" / "&COUNTA(A2:A19) -> 0 / 18

Sheet 1967
A1: Title | B1: Priority | C1: Genre | D1: Status | E1: Curator Tags | F1: Source
A2: Argoman the Fantastic Superman | B2: B | C2: Other / Unclassified | D2: ☐ | E2: Genre Deep Cut / Needs Genre Review | F2: Original Master v1 — curated research basis
A3: Branded to Kill | B3: A | C3: Other / Unclassified | D3: ☐ | E3: Cult Canon / Needs Genre Review | F3: Original Master v1 — curated research basis
A4: David Holzman's Diary | B4: A | C4: Mockumentary Foundation / Meta-Cinema / American Indie | D4: ☐ | E4: Genre Foundation | F4: https://en.wikipedia.org/wiki/David_Holzman%27s_Diary
A5: One-Armed Swordsman | B5: A | C5: Classic Hong Kong Kung Fu / Wuxia / Shaw Brothers | D5: ☐ | E5: Cult Canon | F5: https://www.bfi.org.uk/lists/10-great-wuxia-swordplay-films
A6: Point Blank | B6: A | C6: Crime / Noir | D6: ☐ | E6: Cult Canon | F6: Original Master v1 — curated research basis
A7: Privilege | B7: A | C7: Sci-Fi / Dystopian | D7: ☐ | E7: Cult Canon | F7: Original Master v1 — curated research basis
A8: Quatermass and the Pit | B8: A | C8: Sci-Fi Horror | D8: ☐ | E8: Genre Essential | F8: Original Master v1 — curated research basis
A9: Samurai Rebellion | B9: B | C9: Arthouse | D9: ☐ | E9: Genre Deep Cut | F9: Original Master v1 — curated research basis
A10: She Freak | B10: A | C10: Exploitation | D10: ☐ | E10: Genre Essential | F10: Original Master v1 — curated research basis
A11: The Fearless Vampire Killers | B11: B | C11: Horror Comedy | D11: ☐ | E11: Genre Deep Cut | F11: Original Master v1 — curated research basis
A12: The Gruesome Twosome | B12: A | C12: Other / Unclassified | D12: ☐ | E12: Cult Canon / Needs Genre Review | F12: Original Master v1 — curated research basis
... A17: This Night I'll Possess Your Corpse | B17: A | C17: Horror — Subgenre Review | D17: ☐ | E17: Genre Essential | F17: Original Master v1 — curated research basis
C19: In collectie | D19: =COUNTIF(D2:D17,"☑")&" / "&COUNTA(A2:A17) -> 0 / 16

Sheet 1968
A1: Title | B1: Priority | C1: Genre | D1: Status | E1: Curator Tags | F1: Source
A2: Barbarella | B2: A | C2: Sci-Fi / Comedy / Camp | D2: ☐ | E2: Camp Classic | F2: Original Master v1 — curated research basis
A3: Danger: Diabolik | B3: A | C3: Other / Unclassified | D3: ☐ | E3: Cult Canon / Needs Genre Review | F3: Original Master v1 — curated research basis
A4: Destroy All Monsters | B4: A | C4: Kaiju / Tokusatsu / Monster Ensemble | D4: ☐ | E4: Cult Canon / Franchise Essential | F4: SOURCE AUDIT NEEDED — final blind-spot pass
A5: Goke, Body Snatcher from Hell | B5: A | C5: Sci-Fi Horror | D5: ☐ | E5: Genre Essential | F5: Original Master v1 — curated research basis
A6: Head | B6: A | C6: Music / Psychedelic | D6: ☐ | E6: Visual Cult | F6: SOURCE AUDIT NEEDED — row-level external source not retained
A7: Hour of the Wolf | B7: A | C7: Psychological Horror / Folk Horror / Hallucinatory Reality | D7: ☐ | E7: Cult Canon / Genre Essential / Visual Cult | F7: https://www.bfi.org.uk/features/ingmar-bergman-folk-horror-pioneer
A8: Night of the Living Dead | B8: A | C8: Zombie Horror / Siege Horror | D8: ☐ | E8: Genre Essential | F8: Original Master v1 — curated research basis
A9: Planet of the Apes | B9: C | C9: Dystopian Sci-Fi / Social Sci-Fi / Post-Apocalyptic | D9: ☐ | E9: Canon Anchor / Genre Essential | F9: https://en.wikipedia.org/wiki/Planet_of_the_Apes_(1968_film)
A10: Rosemary's Baby | B10: C | C10: Psychological Horror / Occult Horror / Apartment Paranoia | D10: ☐ | E10: Canon Anchor / Genre Essential | F10: Original Master v1 — curated research basis
A11: Spirits of the Dead | B11: B | C11: Horror Anthology | D11: ☐ | E11: Genre Deep Cut | F11: Original Master v1 — curated research basis
A12: Symbiopsychotaxiplasm: Take One | B12: A | C12: Experimental | D12: ☐ | E12: Cult Canon | F12: Original Master v1 — curated research basis
... A24: Yellow Submarine | B24: A | C24: Animation / Music / Psychedelic | D24: ☐ | E24: Visual Cult | F24: SOURCE AUDIT NEEDED — row-level external source not retained
C26: In collectie | D26: =COUNTIF(D2:D24,"☑")&" / "&COUNTA(A2:A24) -> 0 / 23

Sheet 1969
A1: Title | B1: Priority | C1: Genre | D1: Status | E1: Curator Tags | F1: Source
A2: All Monsters Attack | B2: B | C2: Kaiju / Kids Fantasy / Franchise Oddity | D2: ☐ | E2: Franchise Deep Cut / Cult Oddity | F2: SOURCE AUDIT NEEDED — final blind-spot pass
A3: All the Colors of the Dark | B3: A | C3: Giallo | D3: ☐ | E3: Visual Cult | F3: Original Master v1 — curated research basis
A4: Blind Beast | B4: A | C4: Arthouse | D4: ☐ | E4: Genre Essential | F4: Original Master v1 — curated research basis
A5: Fando y Lis | B5: A | C5: Arthouse / Surreal | D5: ☐ | E5: Cult Canon | F5: Original Master v1 — curated research basis
A6: Funeral Parade of Roses | B6: A | C6: Arthouse | D6: ☐ | E6: Cult Canon | F6: Original Master v1 — curated research basis
A7: Horrors of Malformed Men | B7: A | C7: Other / Unclassified | D7: ☐ | E7: Cult Canon / Needs Genre Review | F7: Original Master v1 — curated research basis
A8: Stereo | B8: A | C8: Sci-Fi / Experimental | D8: ☐ | E8: Genre Essential | F8: Original Master v1 — curated research basis
A9: The Bed Sitting Room | B9: A | C9: Post-Apocalyptic / Arthouse / Absurdist | D9: ☐ | E9: Genre Essential | F9: https://www.mondo-digital.com/bronxwarriors.html
A10: The Cremator | B10: A | C10: Psychological Horror / Black Comedy / Surrealism | D10: ☐ | E10: Cult Canon / Visual Cult / Genre Deep Cut | F10: Original Master v1 — curated research basis
A11: The Haunted House of Horror | B11: B | C11: Horror — Subgenre Review | D11: ☐ | E11: Genre Deep Cut | F11: Original Master v1 — curated research basis
A12: The Illustrated Man | B12: B | C12: Sci-Fi | D12: ☐ | E12: Cult Oddity | F12: Original Master v1 — curated research basis
... A15: Venus in Furs | B15: A | C15: Erotic | D15: ☐ | E15: Visual Cult | F15: Original Master v1 — curated research basis
C17: In collectie | D17: =COUNTIF(D2:D15,"☑")&" / "&COUNTA(A2:A15) -> 0 / 14

Sheet 1970
A1: Title | B1: Priority | C1: Genre | D1: Status | E1: Curator Tags | F1: Source
A2: A Walk In The Spring Rain | B2: B | C2: Other / Unclassified | D2: ☐ | E2: Genre Deep Cut / Needs Genre Review | F2: Original Master v1 — curated research basis
A3: Adam At Six A.M | B3: B | C3: Other / Unclassified | D3: ☐ | E3: Genre Deep Cut / Needs Genre Review | F3: Original Master v1 — curated research basis
A4: Airport | B4: B | C4: Other / Unclassified | D4: ☐ | E4: Genre Deep Cut / Needs Genre Review | F4: Original Master v1 — curated research basis
A5: And Soon The Darkness | B5: B | C5: Other / Unclassified | D5: ☐ | E5: Genre Deep Cut / Needs Genre Review | F5: Original Master v1 — curated research basis
A6: Angel Unchained | B6: B | C6: Other / Unclassified | D6: ☐ | E6: Genre Deep Cut / Needs Genre Review | F6: Original Master v1 — curated research basis
A7: Beast of Blood | B7: B | C7: Exploitation Horror | D7: ☐ | E7: Genre Deep Cut | F7: Original Master v1 — curated research basis
A8: Beneath the Planet of the Apes | B8: B | C8: Dystopian Sci-Fi / Post-Apocalyptic / Mutant Cult | D8: ☐ | E8: Franchise Essential / Genre Deep Cut | F8: https://en.wikipedia.org/wiki/Beneath_the_Planet_of_the_Apes
A9: Beyond the Valley of the Dolls | B9: A | C9: Comedy / Camp | D9: ☐ | E9: Camp Classic | F9: Original Master v1 — curated research basis
A10: Bigfoot The Movie | B10: B | C10: Other / Unclassified | D10: ☐ | E10: Genre Deep Cut / Needs Genre Review | F10: Original Master v1 — curated research basis
A11: Bombay Talkie | B11: B | C11: Other / Unclassified | D11: ☐ | E11: Genre Deep Cut / Needs Genre Review | F11: Original Master v1 — curated research basis
A12: Carry On Up the Jungle | B12: B | C12: Other / Unclassified | D12: ☐ | E12: Genre Deep Cut / Needs Genre Review | F12: Original Master v1 — curated research basis
... A65: Wuthering Heights | B65: B | C65: Other / Unclassified | D65: ☐ | E65: Genre Deep Cut / Needs Genre Review | F65: Original Master v1 — curated research basis
C67: In collectie | D67: =COUNTIF(D2:D65,"☑")&" / "&COUNTA(A2:A65) -> 0 / 64

Sheet 1971
A1: Title | B1: Priority | C1: Genre | D1: Status | E1: Curator Tags | F1: Source
A2: $ | B2: B | C2: Other / Unclassified | D2: ☐ | E2: Genre Deep Cut / Needs Genre Review | F2: Original Master v1 — curated research basis
A3: 200 Motels | B3: B | C3: Other / Unclassified | D3: ☐ | E3: Genre Deep Cut / Needs Genre Review | F3: Original Master v1 — curated research basis
A4: A Clockwork Orange | B4: C | C4: Sci-Fi / Dystopian | D4: ☐ | E4: Cult Canon / Canon Anchor | F4: Original Master v1 — curated research basis
A5: A Lizard in a Woman's Skin | B5: A | C5: Giallo / Psychological Thriller / Psychedelic | D5: ☐ | E5: Genre Essential / Visual Cult | F5: SOURCE AUDIT NEEDED — final blind-spot pass
A6: A Lizard in a Woman's Skin/Schizoid | B6: B | C6: Other / Unclassified | D6: ☐ | E6: Genre Deep Cut / Needs Genre Review | F6: Original Master v1 — curated research basis
A7: A Touch of Zen | B7: A | C7: Classic Hong Kong Martial Arts / Wuxia / King Hu / Arthouse Cult | D7: ☐ | E7: Cult Canon | F7: https://www.bfi.org.uk/lists/great-action-film-every-year-1924-now
A8: A Town Called Hell | B8: B | C8: Exploitation Horror | D8: ☐ | E8: Genre Deep Cut | F8: Original Master v1 — curated research basis
A9: Beast of the Yellow Night | B9: B | C9: Other / Unclassified | D9: ☐ | E9: Genre Deep Cut / Needs Genre Review | F9: Original Master v1 — curated research basis
A10: Black Beauty | B10: B | C10: Other / Unclassified | D10: ☐ | E10: Genre Deep Cut / Needs Genre Review | F10: Original Master v1 — curated research basis
A11: Bunny O'Hare | B11: B | C11: Other / Unclassified | D11: ☐ | E11: Genre Deep Cut / Needs Genre Review | F11: Original Master v1 — curated research basis
A12: Carnal Knowledge | B12: B | C12: Other / Unclassified | D12: ☐ | E12: Genre Deep Cut / Needs Genre Review | F12: Original Master v1 — curated research basis
... A75: Women In Cages | B75: B | C75: Other / Unclassified | D75: ☐ | E75: Genre Deep Cut / Needs Genre Review | F75: Original Master v1 — curated research basis
C77: In collectie | D77: =COUNTIF(D2:D75,"☑")&" / "&COUNTA(A2:A75) -> 0 / 74

Sheet 1972
A1: Title | B1: Priority | C1: Genre | D1: Status | E1: Curator Tags | F1: Source
A2: 43: The Richard Petty Story | B2: B | C2: Other / Unclassified | D2: ☐ | E2: Genre Deep Cut / Needs Genre Review | F2: Original Master v1 — curated research basis
A3: A Reason to Live, a Reason to Die | B3: B | C3: Other / Unclassified | D3: ☐ | E3: Genre Deep Cut / Needs Genre Review | F3: Original Master v1 — curated research basis
A4: Across 110th Street | B4: B | C4: Other / Unclassified | D4: ☐ | E4: Genre Deep Cut / Needs Genre Review | F4: Original Master v1 — curated research basis
A5: Asylum | B5: B | C5: Other / Unclassified | D5: ☐ | E5: Genre Deep Cut / Needs Genre Review | F5: Original Master v1 — curated research basis
A6: Beware! The Blob | B6: B | C6: Other / Unclassified | D6: ☐ | E6: Genre Deep Cut / Needs Genre Review | F6: Original Master v1 — curated research basis
A7: Blacula | B7: A | C7: Horror — Subgenre Review | D7: ☐ | E7: Genre Essential | F7: Original Master v1 — curated research basis
A8: Blood Freak | B8: B | C8: Exploitation Horror | D8: ☐ | E8: Genre Deep Cut | F8: Original Master v1 — curated research basis
A9: Buck and the Preacher | B9: A | C9: Black Western / Adventure | D9: ☐ | E9: Genre Essential | F9: SOURCE AUDIT NEEDED — row-level external source not retained
A10: Bury Me an Angel | B10: B | C10: Other / Unclassified | D10: ☐ | E10: Genre Deep Cut / Needs Genre Review | F10: Original Master v1 — curated research basis
A11: Butterflies Are Free | B11: B | C11: Other / Unclassified | D11: ☐ | E11: Genre Deep Cut / Needs Genre Review | F11: Original Master v1 — curated research basis
A12: Cabaret | B12: A | C12: Musical / Drama / Arthouse | D12: ☐ | E12: Genre Essential | F12: SOURCE AUDIT NEEDED — row-level external source not retained
... A73: You'll Like My Mother | B73: B | C73: Other / Unclassified | D73: ☐ | E73: Genre Deep Cut / Needs Genre Review | F73: Original Master v1 — curated research basis
C75: In collectie | D75: =COUNTIF(D2:D73,"☑")&" / "&COUNTA(A2:A73) -> 0 / 72

Sheet 1973
A1: Title | B1: Priority | C1: Genre | D1: Status | E1: Curator Tags | F1: Source
A2: A Name For Evil | B2: B | C2: Exploitation Horror | D2: ☐ | E2: Genre Deep Cut | F2: Original Master v1 — curated research basis
A3: A Warm December | B3: B | C3: Other / Unclassified | D3: ☐ | E3: Genre Deep Cut / Needs Genre Review | F3: Original Master v1 — curated research basis
A4: Ace Eli and Rodger of the Skies | B4: B | C4: Other / Unclassified | D4: ☐ | E4: Genre Deep Cut / Needs Genre Review | F4: Original Master v1 — curated research basis
A5: Alvin Purple | B5: B | C5: Ozploitation / Ocker Comedy / Sex Comedy | D5: ☐ | E5: Genre Deep Cut | F5: https://www.bfi.org.uk/features/fast-track-fandom-beginners-guide-through-ozploitation-movies
A6: And Now the Screaming Starts! | B6: B | C6: Sci-Fi / Fantasy | D6: ☐ | E6: Genre Deep Cut | F6: Original Master v1 — curated research basis
A7: Arnold | B7: B | C7: Other / Unclassified | D7: ☐ | E7: Genre Deep Cut / Needs Genre Review | F7: Original Master v1 — curated research basis
A8: Badlands | B8: B | C8: Other / Unclassified | D8: ☐ | E8: Genre Deep Cut / Needs Genre Review | F8: Original Master v1 — curated research basis
A9: Baffled! | B9: B | C9: Other / Unclassified | D9: ☐ | E9: Genre Deep Cut / Needs Genre Review | F9: Original Master v1 — curated research basis
A10: Battle for the Planet of the Apes | B10: B | C10: Post-Apocalyptic Sci-Fi / Franchise / Social Sci-Fi | D10: ☐ | E10: Franchise Deep Cut / Completion | F10: https://en.wikipedia.org/wiki/Battle_for_the_Planet_of_the_Apes
A11: Belladonna of Sadness | B11: A | C11: Adult Animation / Psychedelic / Arthouse | D11: ☐ | E11: Visual Cult | F11: https://www.bfi.org.uk/sight-and-sound/lists/50-key-anime-films
A12: Beyond Atlantis | B12: B | C12: Other / Unclassified | D12: ☐ | E12: Genre Deep Cut / Needs Genre Review | F12: Original Master v1 — curated research basis
... A78: Your Three Minutes Are Up | B78: B | C78: Other / Unclassified | D78: ☐ | E78: Genre Deep Cut / Needs Genre Review | F78: Original Master v1 — curated research basis
C80: In collectie | D80: =COUNTIF(D2:D78,"☑")&" / "&COUNTA(A2:A78) -> 0 / 77

Sheet 1974
A1: Title | B1: Priority | C1: Genre | D1: Status | E1: Curator Tags | F1: Source
A2: A Quiet Day in Belfast | B2: B | C2: Other / Unclassified | D2: ☐ | E2: Genre Deep Cut / Needs Genre Review | F2: Original Master v1 — curated research basis
A3: Abby | B3: B | C3: Other / Unclassified | D3: ☐ | E3: Genre Deep Cut / Needs Genre Review | F3: Original Master v1 — curated research basis
A4: Act Of Vengeance | B4: B | C4: Other / Unclassified | D4: ☐ | E4: Genre Deep Cut / Needs Genre Review | F4: Original Master v1 — curated research basis
A5: Almost Human | B5: A | C5: Poliziotteschi / Eurocrime / Serial Criminal / Nihilistic Cult | D5: ☐ | E5: Genre Essential | F5: https://en.wikipedia.org/wiki/Poliziotteschi
A6: Bad Ronald | B6: A | C6: Made-for-TV Thriller / Psychological Horror / Hidden-Room Horror | D6: ☐ | E6: TV Cult / Cult Classic | F6: SOURCE AUDIT NEEDED — final blind-spot pass
A7: Benji | B7: B | C7: Other / Unclassified | D7: ☐ | E7: Genre Deep Cut / Needs Genre Review | F7: Original Master v1 — curated research basis
A8: Big Bad Mama | B8: B | C8: Other / Unclassified | D8: ☐ | E8: Genre Deep Cut / Needs Genre Review | F8: Original Master v1 — curated research basis
A9: Black Belt Jones | B9: B | C9: Blaxploitation / Martial Arts / Action | D9: ☐ | E9: Genre Deep Cut | F9: Original Master v1 — curated research basis
A10: Black Christmas | B10: A | C10: Proto-Slasher | D10: ☐ | E10: Genre Foundation | F10: Original Master v1 — curated research basis
A11: Black Streetfighter/Black Fist | B11: B | C11: Other / Unclassified | D11: ☐ | E11: Genre Deep Cut / Needs Genre Review | F11: Original Master v1 — curated research basis
A12: Blueblood | B12: B | C12: Exploitation Horror | D12: ☐ | E12: Genre Deep Cut | F12: Original Master v1 — curated research basis
... A67: Zardoz | B67: A | C67: Sci-Fi | D67: ☐ | E67: Cult Oddity | F67: Original Master v1 — curated research basis
C69: In collectie | D69: =COUNTIF(D2:D67,"☑")&" / "&COUNTA(A2:A67) -> 0 / 66

Sheet 1975
A1: Title | B1: Priority | C1: Genre | D1: Status | E1: Curator Tags | F1: Source
A2: 92 in the Shade | B2: B | C2: Other / Unclassified | D2: ☐ | E2: Genre Deep Cut / Needs Genre Review | F2: Original Master v1 — curated research basis
A3: A Boy and His Dog | B3: A | C3: Post-Apocalyptic / Dark Comedy | D3: ☐ | E3: Cult Canon | F3: https://www.mondo-digital.com/bronxwarriors.html
A4: Bad, Black and Beautiful | B4: B | C4: Other / Unclassified | D4: ☐ | E4: Genre Deep Cut / Needs Genre Review | F4: Original Master v1 — curated research basis
A5: Barry Lyndon | B5: B | C5: Other / Unclassified | D5: ☐ | E5: Genre Deep Cut / Needs Genre Review | F5: Original Master v1 — curated research basis
A6: Cooley High | B6: A | C6: Black Cinema / Coming-of-age / Comedy-Drama | D6: ☐ | E6: Genre Essential | F6: SOURCE AUDIT NEEDED — row-level external source not retained
A7: Coonskin | B7: A | C7: Adult Animation / Satire / Blaxploitation Deconstruction | D7: ☐ | E7: Cult Canon | F7: https://www.bfi.org.uk/lists/10-great-blaxploitation-movies
A8: Deafula | B8: B | C8: Other / Unclassified | D8: ☐ | E8: Genre Deep Cut / Needs Genre Review | F8: Original Master v1 — curated research basis
A9: Death Race 2000 | B9: A | C9: Exploitation Horror | D9: ☐ | E9: Genre Essential | F9: Original Master v1 — curated research basis
A10: Deep Red | B10: A | C10: Giallo | D10: ☐ | E10: Genre Essential | F10: Original Master v1 — curated research basis
A11: Dersu Uzala | B11: B | C11: Other / Unclassified | D11: ☐ | E11: Genre Deep Cut / Needs Genre Review | F11: Original Master v1 — curated research basis
A12: Dolemite | B12: A | C12: Blaxploitation / Comedy / Martial Arts | D12: ☐ | E12: Cult Canon | F12: SOURCE AUDIT NEEDED — row-level external source not retained
... A54: Zorro | B54: B | C54: Other / Unclassified | D54: ☐ | E54: Genre Deep Cut / Needs Genre Review | F54: Original Master v1 — curated research basis
C56: In collectie | D56: =COUNTIF(D2:D54,"☑")&" / "&COUNTA(A2:A54) -> 0 / 53

Sheet 1976
A1: Title | B1: Priority | C1: Genre | D1: Status | E1: Curator Tags | F1: Source
A2: Aces High | B2: B | C2: Other / Unclassified | D2: ☐ | E2: Genre Deep Cut / Needs Genre Review | F2: Original Master v1 — curated research basis
A3: Alice, Sweet Alice | B3: A | C3: Slasher / Religious Horror | D3: ☐ | E3: Cult Canon | F3: Original Master v1 — curated research basis
A4: Apple Pie | B4: B | C4: Other / Unclassified | D4: ☐ | E4: Genre Deep Cut / Needs Genre Review | F4: Original Master v1 — curated research basis
A5: Assault on Precinct 13 | B5: A | C5: Action | D5: ☐ | E5: Cult Canon | F5: Original Master v1 — curated research basis
A6: Bittersweet Love | B6: B | C6: Other / Unclassified | D6: ☐ | E6: Genre Deep Cut / Needs Genre Review | F6: Original Master v1 — curated research basis
A7: Black Samurai | B7: B | C7: Blaxploitation / Martial Arts / Action | D7: ☐ | E7: Genre Deep Cut | F7: SOURCE AUDIT NEEDED — row-level external source not retained
A8: Bloodsucking Freaks | B8: B | C8: Exploitation Horror | D8: ☐ | E8: Genre Deep Cut | F8: Original Master v1 — curated research basis
A9: Bruce Lee Fights Back from the Grave | B9: A | C9: Bruceploitation / Exploitation Marketing / Kung Fu Cult | D9: ☐ | E9: Cult Canon | F9: https://en.wikipedia.org/wiki/Bruce_Lee_Fights_Back_from_the_Grave
A10: Bugsy Malone | B10: B | C10: Other / Unclassified | D10: ☐ | E10: Genre Deep Cut / Needs Genre Review | F10: Original Master v1 — curated research basis
A11: Burnt Offerings | B11: B | C11: Psychological Horror / Haunted House / Possession | D11: ☐ | E11: Genre Deep Cut / Slow-Burn Cult | F11: Original Master v1 — curated research basis
A12: Car Wash | B12: A | C12: Black Ensemble Comedy / Music | D12: ☐ | E12: Genre Essential | F12: SOURCE AUDIT NEEDED — row-level external source not retained
... A64: Track of the Moon Beast | B64: B | C64: Other / Unclassified | D64: ☐ | E64: Genre Deep Cut / Needs Genre Review | F64: Original Master v1 — curated research basis
C66: In collectie | D66: =COUNTIF(D2:D64,"☑")&" / "&COUNTA(A2:A64) -> 0 / 63

Sheet 1977
A1: Title | B1: Priority | C1: Genre | D1: Status | E1: Curator Tags | F1: Source
A2: 3 Women | B2: B | C2: Psychological Surrealism / Identity Horror / Dream Logic | D2: ☐ | E2: Genre Deep Cut / Visual Cult / Identity Cinema | F2: Original Master v1 — curated research basis
A3: A Little Night Music | B3: B | C3: Other / Unclassified | D3: ☐ | E3: Genre Deep Cut / Needs Genre Review | F3: Original Master v1 — curated research basis
A4: ABBA: The Movie | B4: B | C4: Other / Unclassified | D4: ☐ | E4: Genre Deep Cut / Needs Genre Review | F4: Original Master v1 — curated research basis
A5: Blue Sunshine | B5: A | C5: Other / Unclassified | D5: ☐ | E5: Cult Canon / Needs Genre Review | F5: Original Master v1 — curated research basis
A6: Bobby Deerfield | B6: B | C6: Other / Unclassified | D6: ☐ | E6: Genre Deep Cut / Needs Genre Review | F6: Original Master v1 — curated research basis
A7: Checkered Flag or Crash | B7: B | C7: Other / Unclassified | D7: ☐ | E7: Genre Deep Cut / Needs Genre Review | F7: Original Master v1 — curated research basis
A8: Close Encounters of the Third Kind | B8: B | C8: Other / Unclassified | D8: ☐ | E8: Genre Deep Cut / Needs Genre Review | F8: Original Master v1 — curated research basis
A9: Damnation Alley | B9: B | C9: Post-Apocalyptic / Road Movie / Sci-Fi | D9: ☐ | E9: Genre Deep Cut | F9: https://www.mondo-digital.com/bronxwarriors.html
A10: Death Bed: The Bed That Eats | B10: A | C10: Outsider Horror / Surreal Regional / Killer Object | D10: ☐ | E10: Cult Oddity / Regional Oddity / Psychotronic | F10: https://en.wikipedia.org/wiki/Death_Bed:_The_Bed_That_Eats
A11: Death Promise | B11: B | C11: Exploitation Horror | D11: ☐ | E11: Genre Deep Cut | F11: Original Master v1 — curated research basis
A12: Demon Seed | B12: A | C12: Exploitation Horror | D12: ☐ | E12: Genre Essential | F12: Original Master v1 — curated research basis
... A56: You Light Up My Life | B56: B | C56: Other / Unclassified | D56: ☐ | E56: Genre Deep Cut / Needs Genre Review | F56: Original Master v1 — curated research basis
C58: In collectie | D58: =COUNTIF(D2:D56,"☑")&" / "&COUNTA(A2:A56) -> 0 / 55

Sheet 1978
A1: Title | B1: Priority | C1: Genre | D1: Status | E1: Curator Tags | F1: Source
A2: A Dream Of Passion | B2: B | C2: Other / Unclassified | D2: ☐ | E2: Genre Deep Cut / Needs Genre Review | F2: Original Master v1 — curated research basis
A3: Animal House | B3: A | C3: College Comedy / Raunch | D3: ☐ | E3: Cult Canon | F3: SOURCE AUDIT NEEDED — row-level external source not retained
A4: Avalanche | B4: B | C4: Other / Unclassified | D4: ☐ | E4: Genre Deep Cut / Needs Genre Review | F4: Original Master v1 — curated research basis
A5: Big Wednesday | B5: B | C5: Other / Unclassified | D5: ☐ | E5: Genre Deep Cut / Needs Genre Review | F5: Original Master v1 — curated research basis
A6: Blue Collar | B6: A | C6: Black Cinema / Crime / Working-Class Drama | D6: ☐ | E6: Genre Essential | F6: Original Master v1 — curated research basis
A7: Crippled Avengers | B7: A | C7: Classic Kung Fu / Shaw Brothers / Venom Mob | D7: ☐ | E7: Cult Canon | F7: https://www.bfi.org.uk/features/where-begin-with-shaw-brothers
A8: Cycle Vixens | B8: B | C8: Other / Unclassified | D8: ☐ | E8: Genre Deep Cut / Needs Genre Review | F8: Original Master v1 — curated research basis
A9: Dawn of the Dead | B9: A | C9: Zombie Horror | D9: ☐ | E9: Cult Canon | F9: Original Master v1 — curated research basis
A10: Deathsport | B10: B | C10: Exploitation Horror | D10: ☐ | E10: Genre Deep Cut | F10: Original Master v1 — curated research basis
A11: Disco Fever | B11: B | C11: Disco / Drama | D11: ☐ | E11: Genre Deep Cut | F11: Original Master v1 — curated research basis
A12: Drunken Master | B12: A | C12: Classic Kung Fu / Jackie Chan / Comedy | D12: ☐ | E12: Cult Canon / Genre Essential | F12: https://www.bfi.org.uk/lists/10-great-kung-fu-films
... A69: Who Is Killing the Great Chefs of Europe? | B69: B | C69: Other / Unclassified | D69: ☐ | E69: Genre Deep Cut / Needs Genre Review | F69: Original Master v1 — curated research basis
C71: In collectie | D71: =COUNTIF(D2:D69,"☑")&" / "&COUNTA(A2:A69) -> 0 / 68

Sheet 1979
A1: Title | B1: Priority | C1: Genre | D1: Status | E1: Curator Tags | F1: Source
A2: Alien | B2: C | C2: Sci-Fi Horror | D2: ☐ | E2: Canon Anchor | F2: Original Master v1 — curated research basis
A3: All That Jazz | B3: A | C3: Musical / Dance / Arthouse | D3: ☐ | E3: Genre Essential | F3: SOURCE AUDIT NEEDED — row-level external source not retained
A4: Americathon | B4: B | C4: Other / Unclassified | D4: ☐ | E4: Genre Deep Cut / Needs Genre Review | F4: Original Master v1 — curated research basis
A5: Caligula | B5: A | C5: Erotic Historical / Exploitation / Notorious Production | D5: ☐ | E5: Notorious Cult / Alternate Cut History / Banned / Controversial | F5: SOURCE AUDIT NEEDED — final blind-spot pass
A6: Chapter Two | B6: B | C6: Other / Unclassified | D6: ☐ | E6: Genre Deep Cut / Needs Genre Review | F6: Original Master v1 — curated research basis
A7: Chilly Scenes Of Winter | B7: B | C7: Other / Unclassified | D7: ☐ | E7: Genre Deep Cut / Needs Genre Review | F7: Original Master v1 — curated research basis
A8: Cuba | B8: B | C8: Other / Unclassified | D8: ☐ | E8: Genre Deep Cut / Needs Genre Review | F8: Original Master v1 — curated research basis
A9: Dirty Ho | B9: A | C9: Classic Kung Fu / Shaw Brothers / Lau Kar-leung | D9: ☐ | E9: Cult Canon | F9: https://www.bfi.org.uk/features/where-begin-with-shaw-brothers
A10: Disco Godfather | B10: B | C10: Disco / Blaxploitation | D10: ☐ | E10: Genre Deep Cut | F10: Original Master v1 — curated research basis
A11: Hair | B11: A | C11: Rock Musical / Counterculture | D11: ☐ | E11: Soundtrack Cult | F11: SOURCE AUDIT NEEDED — row-level external source not retained
A12: Human Experiments | B12: B | C12: Other / Unclassified | D12: ☐ | E12: Genre Deep Cut / Needs Genre Review | F12: Original Master v1 — curated research basis
... A55: Weasels Rip My Flesh | B55: B | C55: Other / Unclassified | D55: ☐ | E55: Genre Deep Cut / Needs Genre Review | F55: Original Master v1 — curated research basis
C57: In collectie | D57: =COUNTIF(D2:D55,"☑")&" / "&COUNTA(A2:A55) -> 0 / 54

Sheet 1980
A1: Title | B1: Priority | C1: Genre | D1: Status | E1: Curator Tags | F1: Source
A2: Airplane! | B2: A | C2: Spoof / Parody / Slapstick | D2: ☐ | E2: Genre Essential | F2: SOURCE AUDIT NEEDED — row-level external source not retained
A3: Alligator | B3: A | C3: Creature Feature | D3: ☐ | E3: Creature Feature | F3: Original Master v1 — curated research basis
A4: Altered States | B4: A | C4: Body Horror | D4: ☐ | E4: Visual Cult | F4: https://www.criterion.com/films/29506-altered-states
A5: Atlantic City | B5: B | C5: Other / Unclassified | D5: ☐ | E5: Genre Deep Cut / Needs Genre Review | F5: Original Master v1 — curated research basis
A6: Battle Beyond the Stars | B6: A | C6: Sci-Fi | D6: ☐ | E6: Genre Essential | F6: Original Master v1 — curated research basis
A7: Blank Generation | B7: A | C7: No Wave Cinema / Punk Drama / Downtown New York | D7: ☐ | E7: Cult Classic / Time Capsule / Music Cult | F7: SOURCE AUDIT NEEDED — final blind-spot pass
A8: Breaking Glass | B8: A | C8: Music / Punk / Drama | D8: ☐ | E8: Genre Essential | F8: SOURCE AUDIT NEEDED — row-level external source not retained
A9: Caddyshack | B9: A | C9: Sports Comedy / Ensemble | D9: ☐ | E9: Cult Canon | F9: SOURCE AUDIT NEEDED — row-level external source not retained
A10: Can't Stop the Music | B10: A | C10: Disco / Musical / Camp | D10: ☐ | E10: Camp Classic | F10: Original Master v1 — curated research basis
A11: Cannibal Apocalypse | B11: B | C11: Exploitation Horror | D11: ☐ | E11: Genre Deep Cut | F11: Original Master v1 — curated research basis
A12: Cannibal Holocaust | B12: A | C12: Exploitation | D12: ☐ | E12: Banned / Controversial | F12: Original Master v1 — curated research basis
... A64: Xanadu | B64: A | C64: Musical / Disco / Fantasy | D64: ☐ | E64: Camp Classic | F64: Original Master v1 — curated research basis
C66: In collectie | D66: =COUNTIF(D2:D64,"☑")&" / "&COUNTA(A2:A64) -> 0 / 63

Sheet 1981
A1: Title | B1: Priority | C1: Genre | D1: Status | E1: Curator Tags | F1: Source
A2: Alison's Birthday | B2: A | C2: Occult Horror | D2: ☐ | E2: Cult Canon | F2: https://www.nfsa.gov.au/stories/articles/survey-australian-horror-films-1970s-saw-and-babadook
A3: American Pop | B3: A | C3: Adult Animation / Music / Rotoscope | D3: ☐ | E3: Cult Canon | F3: https://www.imdb.com/title/tt0082009/
A4: Americana | B4: B | C4: Other / Unclassified | D4: ☐ | E4: Genre Deep Cut / Needs Genre Review | F4: Original Master v1 — curated research basis
A5: Bloody Birthday | B5: B | C5: Exploitation Horror | D5: ☐ | E5: Genre Deep Cut | F5: Original Master v1 — curated research basis
A6: Blow Out | B6: A | C6: Other / Unclassified | D6: ☐ | E6: Cult Canon / Needs Genre Review | F6: Original Master v1 — curated research basis
A7: Buddy Buddy | B7: B | C7: Other / Unclassified | D7: ☐ | E7: Genre Deep Cut / Needs Genre Review | F7: Original Master v1 — curated research basis
A8: Bustin' Loose | B8: A | C8: Black Comedy / Road / Family | D8: ☐ | E8: Genre Essential | F8: SOURCE AUDIT NEEDED — row-level external source not retained
A9: Carnival Magic | B9: B | C9: Other / Unclassified | D9: ☐ | E9: Genre Deep Cut / Needs Genre Review | F9: Original Master v1 — curated research basis
A10: Caveman | B10: B | C10: Other / Unclassified | D10: ☐ | E10: Genre Deep Cut / Needs Genre Review | F10: Original Master v1 — curated research basis
A11: Cutter's Way | B11: A | C11: Crime / Noir | D11: ☐ | E11: Rediscovered Cult | F11: Original Master v1 — curated research basis
A12: Dark Night of the Scarecrow | B12: A | C12: Made-for-TV Horror / Supernatural Revenge / Rural Horror | D12: ☐ | E12: TV Cult / Cult Classic | F12: SOURCE AUDIT NEEDED — final blind-spot pass
... A91: Zorro: The Gay Blade | B91: B | C91: Other / Unclassified | D91: ☐ | E91: Genre Deep Cut / Needs Genre Review | F91: Original Master v1 — curated research basis
C93: In collectie | D93: =COUNTIF(D2:D91,"☑")&" / "&COUNTA(A2:A91) -> 0 / 90

Sheet 1982
A1: Title | B1: Priority | C1: Genre | D1: Status | E1: Curator Tags | F1: Source
A2: 1990: The Bronx Warriors | B2: B | C2: Italian Post-Apocalyptic / Gang | D2: ☐ | E2: Genre Deep Cut | F2: https://en.wikipedia.org/wiki/1990%3A_The_Bronx_Warriors
A3: 48 Hrs. | B3: A | C3: Buddy Comedy / Action / Black Cinema | D3: ☐ | E3: Genre Essential | F3: SOURCE AUDIT NEEDED — row-level external source not retained
A4: Airplane II: The Sequel | B4: A | C4: Spoof / Parody / Sci-Fi Comedy | D4: ☐ | E4: Genre Essential | F4: SOURCE AUDIT NEEDED — row-level external source not retained
A5: Amityville II: The Possession | B5: B | C5: Other / Unclassified | D5: ☐ | E5: Genre Deep Cut / Needs Genre Review | F5: Original Master v1 — curated research basis
A6: Android | B6: A | C6: Sci-Fi | D6: ☐ | E6: Cult Canon | F6: Original Master v1 — curated research basis
A7: Ator, the Fighting Eagle | B7: A | C7: Sword & Sorcery / Italian Exploitation / Barbarian VHS | D7: ☐ | E7: VHS Classic / Cult Oddity | F7: https://www.cultcelebrities.com/sword-and-sorcery/
A8: Basket Case | B8: A | C8: Exploitation Horror | D8: ☐ | E8: Genre Essential | F8: Original Master v1 — curated research basis
A9: Battletruck / Warlords of the 21st Century | B9: A | C9: Post-Apocalyptic / Road Warrior Clone / Vehicles | D9: ☐ | E9: Genre Essential | F9: https://www.mondo-digital.com/bronxwarriors.html
A10: Best Friends | B10: B | C10: Other / Unclassified | D10: ☐ | E10: Genre Deep Cut / Needs Genre Review | F10: Original Master v1 — curated research basis
A11: Big Meat Eater | B11: B | C11: Other / Unclassified | D11: ☐ | E11: Genre Deep Cut / Needs Genre Review | F11: Original Master v1 — curated research basis
A12: Blade Runner | B12: C | C12: Tech-Noir Anchor / Cyberpunk / Future Noir | D12: ☐ | E12: Cult Canon / Canon Anchor / Genre Foundation | F12: https://www.bfi.org.uk/film/ec064a2a-f7a8-536a-afa2-ed076aad151f/blade-runner
... A85: Wolf Devil Woman | B85: B | C85: Exploitation Horror | D85: ☐ | E85: Genre Deep Cut | F85: Original Master v1 — curated research basis
C87: In collectie | D87: =COUNTIF(D2:D85,"☑")&" / "&COUNTA(A2:A85) -> 0 / 84

Sheet 1983
A1: Title | B1: Priority | C1: Genre | D1: Status | E1: Curator Tags | F1: Source
A2: 2019: After the Fall of New York | B2: A | C2: Italian Post-Nuke / Action | D2: ☐ | E2: Cult Canon | F2: https://www.mondo-digital.com/bronxwarriors.html
A3: 2020 Texas Gladiators | B3: A | C3: Italian Post-Nuke / Action / Mad Max Clone | D3: ☐ | E3: Genre Essential | F3: https://www.imdb.com/title/tt0083565/
A4: A Night in Heaven | B4: B | C4: Other / Unclassified | D4: ☐ | E4: Genre Deep Cut / Needs Genre Review | F4: Original Master v1 — curated research basis
A5: Attack of the Beast Creatures | B5: B | C5: Other / Unclassified | D5: ☐ | E5: Genre Deep Cut / Needs Genre Review | F5: Original Master v1 — curated research basis
A6: BMX Bandits | B6: B | C6: Australian Cult / Youth Action / Bikes | D6: ☐ | E6: Genre Deep Cut | F6: https://www.nfsa.gov.au/stories/articles/ozploitation-films-1970s-and-1980s
A7: Brainstorm | B7: A | C7: Sci-Fi | D7: ☐ | E7: Cult Canon | F7: Original Master v1 — curated research basis
A8: Cross Country | B8: B | C8: Other / Unclassified | D8: ☐ | E8: Genre Deep Cut / Needs Genre Review | F8: Original Master v1 — curated research basis
A9: Curtains | B9: A | C9: Slasher | D9: ☐ | E9: Cult Canon | F9: Original Master v1 — curated research basis
A10: Deathstalker | B10: A | C10: Sword & Sorcery / Corman / Barbarian Exploitation | D10: ☐ | E10: Cult Canon | F10: https://en.wikipedia.org/wiki/Deathstalker_(1983_film)
A11: Eddie And The Cruisers | B11: B | C11: Other / Unclassified | D11: ☐ | E11: Genre Deep Cut / Needs Genre Review | F11: Original Master v1 — curated research basis
A12: Educating Rita | B12: B | C12: Other / Unclassified | D12: ☐ | E12: Genre Deep Cut / Needs Genre Review | F12: Original Master v1 — curated research basis
... A75: Zu: Warriors from the Magic Mountain | B75: A | C75: Fantasy | D75: ☐ | E75: Cult Canon | F75: Original Master v1 — curated research basis
C77: In collectie | D77: =COUNTIF(D2:D75,"☑")&" / "&COUNTA(A2:A75) -> 0 / 74

Sheet 1984
A1: Title | B1: Priority | C1: Genre | D1: Status | E1: Curator Tags | F1: Source
A2: 1984 | B2: B | C2: Other / Unclassified | D2: ☐ | E2: Genre Deep Cut / Needs Genre Review | F2: Original Master v1 — curated research basis
A3: A Soldier's Story | B3: B | C3: Black Cinema / Mystery / Drama | D3: ☐ | E3: Genre Deep Cut | F3: Original Master v1 — curated research basis
A4: All of Me | B4: A | C4: Body-Swap Comedy / Fantasy | D4: ☐ | E4: Genre Essential | F4: SOURCE AUDIT NEEDED — row-level external source not retained
A5: Bachelor Party | B5: A | C5: Raunch Comedy / Party | D5: ☐ | E5: Cult Canon | F5: SOURCE AUDIT NEEDED — row-level external source not retained
A6: Beat Street | B6: A | C6: Hip-Hop / Dance / Music | D6: ☐ | E6: Genre Essential | F6: SOURCE AUDIT NEEDED — row-level external source not retained
A7: Black Devil Doll from Hell | B7: A | C7: Outsider Cinema / SOV Horror / Regional Underground | D7: ☐ | E7: SOV Cult / Regional Oddity / Psychotronic | F7: https://en.wikipedia.org/wiki/Black_Devil_Doll_from_Hell
A8: Blonde Death | B8: A | C8: Outsider Cinema / SOV Crime Comedy / Underground | D8: ☐ | E8: SOV Cult / Regional Oddity / Cult Oddity | F8: https://en.wikipedia.org/wiki/Blonde_Death
A9: Body Double | B9: A | C9: Thriller / Erotic | D9: ☐ | E9: Cult Canon | F9: Original Master v1 — curated research basis
A10: Body Rock | B10: B | C10: Dance / Music | D10: ☐ | E10: Genre Deep Cut | F10: SOURCE AUDIT NEEDED — row-level external source not retained
A11: Breakin' | B11: B | C11: Dance / Hip-Hop | D11: ☐ | E11: Genre Deep Cut | F11: Original Master v1 — curated research basis
A12: Breakin' 2: Electric Boogaloo | B12: A | C12: Dance / Hip-Hop / Camp | D12: ☐ | E12: Camp Classic | F12: SOURCE AUDIT NEEDED — row-level external source not retained
... A70: Wheels on Meals | B70: A | C70: Hong Kong Martial Arts / Jackie Chan / Sammo Hung / Action Comedy | D70: ☐ | E70: Genre Essential | F70: https://en.wikipedia.org/wiki/Wheels_on_Meals
C72: In collectie | D72: =COUNTIF(D2:D70,"☑")&" / "&COUNTA(A2:A70) -> 0 / 69

Sheet 1985
A1: Title | B1: Priority | C1: Genre | D1: Status | E1: Curator Tags | F1: Source
A2: After Hours | B2: A | C2: Surreal / Night Liminal / Dark Comedy | D2: ☐ | E2: Cult Canon | F2: https://www.criterion.com/films/29632-after-hours
A3: American Drive-In | B3: B | C3: Other / Unclassified | D3: ☐ | E3: Genre Deep Cut / Needs Genre Review | F3: Original Master v1 — curated research basis
A4: American Ninja | B4: A | C4: Ninja / Martial Arts VHS / Cannon | D4: ☐ | E4: VHS Classic | F4: https://editorial.rottentomatoes.com/article/top-ten-ninja-films/
A5: Baby: Secret of the Lost Legend | B5: A | C5: High-Concept Family / Video Store Cult / Dinosaur Adventure / Fantasy | D5: ☐ | E5: Forgotten Gem / Video Store Cult / Creature Feature | F5: SOURCE AUDIT NEEDED — high-concept family / video-store cult pass
A6: Back to the Future | B6: A | C6: Sci-Fi Comedy / Time Travel / Teen | D6: ☐ | E6: Genre Essential | F6: SOURCE AUDIT NEEDED — row-level external source not retained
A7: Barbarian Queen | B7: B | C7: Other / Unclassified | D7: ☐ | E7: Genre Deep Cut / Needs Genre Review | F7: Original Master v1 — curated research basis
A8: Better Off Dead | B8: A | C8: Dark Comedy / Comedy / Teen Comedy | D8: ☐ | E8: Cult Canon | F8: Original Master v1 — curated research basis
A9: Blood Cult | B9: A | C9: SOV Horror / Slasher / Home-Video Pioneer | D9: ☐ | E9: SOV Cult / VHS Classic / Genre Foundation | F9: https://www.americangenrefilm.com/theatrical-film-catalog/blood-cult/
A10: Brazil | B10: A | C10: Surreal / Bureaucratic Liminal / Retro-Futurist / Arthouse | D10: ☐ | E10: Genre Essential | F10: https://www.bfi.org.uk/film/bb840dfa-f69d-576b-bd99-dfa28efd4595/brazil
